<?xml version="1.0" encoding="utf-8"?>
<!-- This URDF was automatically created by SolidWorks to URDF Exporter! Originally created by Stephen Brawner (brawner@gmail.com) 
     Commit Version: 1.6.0-4-g7f85cfe  Build Version: 1.6.7995.38578
     For more information, please see http://wiki.ros.org/sw_urdf_exporter -->
<robot
  name="jdcobot_200_description">
  <link
    name="base_link">
    <inertial>
      <origin
        xyz="0.000562757024246966 0.0553111268232362 8.01323732304302E-10"
        rpy="0 0 0" />
      <mass
        value="1.45466230260579" />
      <inertia
        ixx="0.00586037843377662"
        ixy="3.70855294060135E-05"
        ixz="-2.80341788206397E-12"
        iyy="0.00896767875105627"
        iyz="-3.76086880841158E-11"
        izz="0.00580377346334889" />
    </inertial>
    <visual>
      <origin
        xyz="0 0 0"
        rpy="0 0 0" />
      <geometry>
        <mesh
          filename="package://jdcobot_200_description/meshes/base_link.STL" />
      </geometry>
      <material
        name="">
        <color
          rgba="1 1 1 1" />
      </material>
    </visual>
    <collision>
      <origin
        xyz="0 0 0"
        rpy="0 0 0" />
      <geometry>
        <mesh
          filename="package://jdcobot_200_description/meshes/base_link.STL" />
      </geometry>
    </collision>
  </link>
  <link
    name="link_1">
    <inertial>
      <origin
        xyz="-0.00686430187287576 -0.0611677451215621 -3.07255157625046E-15"
        rpy="0 0 0" />
      <mass
        value="0.353787090695809" />
      <inertia
        ixx="0.000417769900292588"
        ixy="-8.77307022551608E-05"
        ixz="-8.54033675269732E-18"
        iyy="0.000338976404100492"
        iyz="-4.5121263711427E-18"
        izz="0.000546340543517855" />
    </inertial>
    <visual>
      <origin
        xyz="0 0 0"
        rpy="0 0 0" />
      <geometry>
        <mesh
          filename="package://jdcobot_200_description/meshes/link_1.STL" />
      </geometry>
      <material
        name="">
        <color
          rgba="1 1 1 1" />
      </material>
    </visual>
    <collision>
      <origin
        xyz="0 0 0"
        rpy="0 0 0" />
      <geometry>
        <mesh
          filename="package://jdcobot_200_description/meshes/link_1.STL" />
      </geometry>
    </collision>
  </link>
  <joint
    name="joint_1"
    type="revolute">
    <origin
      xyz="0 0 0.1"
      rpy="-1.5708 0 -1.5708" />
    <parent
      link="base_link" />
    <child
      link="link_1" />
    <axis
      xyz="0 1 0" />
    <!-- Set appropriate limits -->
    <limit lower="-3.14" upper="3.14" effort="100" velocity="3" />
  </joint>
  <link
    name="link_2">
    <inertial>
      <origin
        xyz="-0.0512205933131344 -0.0568783763544331 -4.06670055236497E-06"
        rpy="0 0 0" />
      <mass
        value="0.463736619092963" />
      <inertia
        ixx="0.0020393996859804"
        ixy="5.56420200364723E-05"
        ixz="7.13268550773058E-05"
        iyy="0.00078084723809914"
        iyz="4.62251136513137E-05"
        izz="0.00224858529254322" />
    </inertial>
    <visual>
      <origin
        xyz="0 0 0"
        rpy="0 0 0" />
      <geometry>
        <mesh
          filename="package://jdcobot_200_description/meshes/link_2.STL" />
      </geometry>
      <material
        name="">
        <color
          rgba="1 1 1 1" />
      </material>
    </visual>
    <collision>
      <origin
        xyz="0 0 0"
        rpy="0 0 0" />
      <geometry>
        <mesh
          filename="package://jdcobot_200_description/meshes/link_2.STL" />
      </geometry>
    </collision>
  </link>
  <joint
    name="joint_2"
    type="revolute">
    <origin
      xyz="-0.06 -0.088 0"
      rpy="0 0 0" />
    <parent
      link="link_1" />
    <child
      link="link_2" />
    <axis
      xyz="1 0 0" />
    <!-- Set appropriate limits -->
    <limit lower="-3.14" upper="3.14" effort="100" velocity="3" />
  </joint>
  <link
    name="link_3">
    <inertial>
      <origin
        xyz="0.051221 -0.056878 4.0667E-06"
        rpy="0 0 0" />
      <mass
        value="0.46374" />
      <inertia
        ixx="0.0020394"
        ixy="-5.5642E-05"
        ixz="7.1327E-05"
        iyy="0.00078085"
        iyz="-4.6225E-05"
        izz="0.0022486" />
    </inertial>
    <visual>
      <origin
        xyz="0 0 0"
        rpy="0 0 0" />
      <geometry>
        <mesh
          filename="package://jdcobot_200_description/meshes/link_3.STL" />
      </geometry>
      <material
        name="">
        <color
          rgba="1 1 1 1" />
      </material>
    </visual>
    <collision>
      <origin
        xyz="0 0 0"
        rpy="0 0 0" />
      <geometry>
        <mesh
          filename="package://jdcobot_200_description/meshes/link_3.STL" />
      </geometry>
    </collision>
  </link>
  <joint
    name="joint_3"
    type="revolute">
    <origin
      xyz="0 -0.11 0"
      rpy="0 0 0" />
    <parent
      link="link_2" />
    <child
      link="link_3" />
    <axis
      xyz="1 0 0" />
    <!-- Set appropriate limits -->
    <limit lower="-3.14" upper="3.14" effort="100" velocity="3" />
  </joint>
  <link
    name="link_4">
    <inertial>
      <origin
        xyz="0.048821 0.022413 -0.00010181"
        rpy="0 0 0" />
      <mass
        value="0.23955" />
      <inertia
        ixx="0.0005247"
        ixy="-3.7421E-05"
        ixz="-5.9367E-05"
        iyy="0.0003591"
        iyz="4.4372E-06"
        izz="0.00057947" />
    </inertial>
    <visual>
      <origin
        xyz="0 0 0"
        rpy="0 0 0" />
      <geometry>
        <mesh
          filename="package://jdcobot_200_description/meshes/link_4.STL" />
      </geometry>
      <material
        name="">
        <color
          rgba="1 1 1 1" />
      </material>
    </visual>
    <collision>
      <origin
        xyz="0 0 0"
        rpy="0 0 0" />
      <geometry>
        <mesh
          filename="package://jdcobot_200_description/meshes/link_4.STL" />
      </geometry>
    </collision>
  </link>
  <joint
    name="joint_4"
    type="revolute">
    <origin
      xyz="0 -0.11 0"
      rpy="0 0 -3.1416" />
    <parent
      link="link_3" />
    <child
      link="link_4" />
    <axis
      xyz="1 0 0" />
    <!-- Set appropriate limits -->
    <limit lower="-3.14" upper="3.14" effort="100" velocity="3" />
  </joint>
  <link
    name="link_5">
    <inertial>
      <origin
        xyz="-0.0488207687805612 0.0224126689652474 0.0001018097402508"
        rpy="0 0 0" />
      <mass
        value="0.239547259500175" />
      <inertia
        ixx="0.000524698163491167"
        ixy="3.74214131540637E-05"
        ixz="-5.9367468239364E-05"
        iyy="0.000359097831103634"
        iyz="-4.43717288201737E-06"
        izz="0.000579467955922389" />
    </inertial>
    <visual>
      <origin
        xyz="0 0 0"
        rpy="0 0 0" />
      <geometry>
        <mesh
          filename="package://jdcobot_200_description/meshes/link_5.STL" />
      </geometry>
      <material
        name="">
        <color
          rgba="1 1 1 1" />
      </material>
    </visual>
    <collision>
      <origin
        xyz="0 0 0"
        rpy="0 0 0" />
      <geometry>
        <mesh
          filename="package://jdcobot_200_description/meshes/link_5.STL" />
      </geometry>
    </collision>
  </link>
  <joint
    name="joint_5"
    type="revolute">
    <origin
      xyz="0.06 0.08 0"
      rpy="0 0 -1.5708" />
    <parent
      link="link_4" />
    <child
      link="link_5" />
    <axis
      xyz="1 0 0" />
    <!-- Set appropriate limits -->
    <limit lower="-3.14" upper="3.14" effort="100" velocity="3" />
  </joint>
</robot>
